<?xml version="1.0"?>
<robot name="merlin" xmlns:xacro="http://www.ros.org/wiki/xacro">
  <xacro:property name="PI" value="3.1415926535897931"/>
  <xacro:property name="mass" value="1"/>

  <xacro:include filename="$(find merlin_description)/urdf/merlin.gazebo" />
  <xacro:include filename="$(find merlin_description)/urdf/materials.xacro" />

  <link name="world"/>

  <joint name="fixed" type="fixed">
    <parent link="world"/>
    <child link="base_link"/>
  </joint>

  <link name="base_link">
    <visual>
      <geometry>
        <box size="0.16 0.16 0.12"/>
      </geometry>
      <origin rpy="0 0 0" xyz="0 0 0.085"/>
      <material name="orange"/>
    </visual>

    <collision>
      <geometry>
        <box size="0.16 0.16 0.12"/>
      </geometry>
      <origin rpy="0 0 0" xyz="0 0 0.085"/>
    </collision>

    <inertial>
      <mass value="${mass}"/>
      <inertia ixx="0.4" ixy="0.0" ixz="0.0" iyy="0.4" iyz="0.0" izz="0.2"/>
    </inertial>
  </link>
  
  <link name="lwheel">
    <visual>
      <geometry>
        <cylinder length="0.008" radius="0.046"/>
      </geometry>
      <origin rpy="0 0 0" xyz="0 0 0"/>
      <material name="orange"/>
    </visual>

    <collision>
      <geometry>
        <cylinder length="0.008" radius="0.046"/>
      </geometry>
      <origin rpy="0 0 0" xyz="0 0 0"/>
    </collision>

    <inertial>
      <mass value="${mass}"/>
      <inertia ixx="0.4" ixy="0.0" ixz="0.0" iyy="0.4" iyz="0.0" izz="0.2"/>
    </inertial>
  </link>
  
  <joint name="base_to_lwheel" type="continuous">
    <parent link="base_link"/>
    <child link="lwheel"/>
    <origin xyz="0 0.115 0.046" rpy="1.5708 0 0"/>
    <axis xyz="0 0 1"/>
  </joint>
  
  <link name="rwheel">
    <visual>
      <geometry>
        <cylinder length="0.008" radius="0.046"/>
      </geometry>
      <origin rpy="0 0 0" xyz="0 0 0"/>
      <material name="black">
        <color rgba="0 0 0 1"/>
      </material>
    </visual>

    <collision>
      <geometry>
        <cylinder length="0.008" radius="0.046"/>
      </geometry>
      <origin rpy="0 0 0" xyz="0 0 0"/>
    </collision>

    <inertial>
      <mass value="${mass}"/>
      <inertia ixx="0.4" ixy="0.0" ixz="0.0" iyy="0.4" iyz="0.0" izz="0.2"/>
    </inertial>
  </link>
  
  <joint name="base_to_rwheel" type="continuous">
    <parent link="base_link"/>
    <child link="rwheel"/>
    <origin xyz="0 -0.115 0.046" rpy="-1.5708 0 0"/>
    <axis xyz="0 0 1"/>
  </joint>
  
  <link name="fwheel_attach">
    <visual>
      <geometry>
        <cylinder length="0.060" radius="0.023"/>
      </geometry>
      <origin rpy="0 0 0" xyz="0.13 0 0.08"/>
      <material name="white">
        <color rgba="1 1 1 1"/>
      </material>
    </visual>

    <collision>
      <geometry>
        <cylinder length="0.060" radius="0.023"/>
      </geometry>
      <origin rpy="0 0 0" xyz="0.13 0 0.08"/>
    </collision>

    <inertial>
      <mass value="${mass}"/>
      <inertia ixx="0.4" ixy="0.0" ixz="0.0" iyy="0.4" iyz="0.0" izz="0.2"/>
    </inertial>
  </link>
  
  <joint name="base_to_fattach" type="fixed">
    <parent link="base_link"/>
    <child link="fwheel_attach"/>
    <origin xyz="0 0 0" rpy="0 0 0"/>
  </joint>
  
  <link name="fwheel">
    <visual>
      <geometry>
        <cylinder length="0.005" radius="0.020"/>
      </geometry>
      <origin rpy="1.578 0 0" xyz="0 0 0"/>
      <material name="black">
        <color rgba="0 0 0 1"/>
      </material>
    </visual>

    <collision>
      <geometry>
        <cylinder length="0.005" radius="0.020"/>
      </geometry>
      <origin rpy="1.578 0 0" xyz="0 0 0"/>
    </collision>

    <inertial>
      <mass value="${mass}"/>
      <inertia ixx="0.4" ixy="0.0" ixz="0.0" iyy="0.4" iyz="0.0" izz="0.2"/>
    </inertial>
  </link>
  
  <joint name="base_to_fwheel" type="continuous">
    <parent link="base_link"/>
    <child link="fwheel"/>
    <origin xyz="0.13 0 0.02" rpy="0 0 0"/>
  </joint>
  
   <transmission name="tran1">
    <type>transmission_interface/SimpleTransmission</type>
    <joint name="base_to_lwheel">
      <hardwareInterface>EffortJointInterface</hardwareInterface>
    </joint>
    <actuator name="motor1">
      <hardwareInterface>EffortJointInterface</hardwareInterface>
      <mechanicalReduction>1</mechanicalReduction>
    </actuator>
  </transmission>

  <transmission name="tran2">
    <type>transmission_interface/SimpleTransmission</type>
    <joint name="base_to_rwheel">
      <hardwareInterface>EffortJointInterface</hardwareInterface>
    </joint>
    <actuator name="motor2">
      <hardwareInterface>EffortJointInterface</hardwareInterface>
      <mechanicalReduction>1</mechanicalReduction>
    </actuator>
  </transmission>

</robot>
